<?xml version="1.0"?>
<robot name="simple_arm">
    <!-- Base Link -->
    <link name="base_link"/>

    <!-- Joint 1 -->
    <joint name="joint1" type="revolute">
        <parent link="base_link"/>
        <child link="link1"/>
        <origin xyz="0 0 0.1" rpy="0 0 0"/>
        <axis xyz="0 0 1"/>
        <limit effort="10" lower="-1.57" upper="1.57" velocity="1.0"/>
    </joint>

    <!-- Link 1 -->
    <link name="link1">
        <inertial>
            <mass value="1.0"/>
            <origin xyz="0 0 0.05"/>
            <inertia ixx="0.01" iyy="0.01" izz="0.01" ixy="0" ixz="0" iyz="0"/>
        </inertial>
    </link>

    <!-- Joint 2 -->
    <joint name="joint2" type="revolute">
        <parent link="link1"/>
        <child link="link2"/>
        <origin xyz="0.1 0 0" rpy="0 0 0"/>
        <axis xyz="0 0 1"/>
        <limit effort="10" lower="-1.57" upper="1.57" velocity="1.0"/>
    </joint>

    <!-- Link 2 (End-Effector) -->
    <link name="link2">
        <inertial>
            <mass value="1.0"/>
            <origin xyz="0 0 0.05"/>
            <inertia ixx="0.01" iyy="0.01" izz="0.01" ixy="0" ixz="0" iyz="0"/>
        </inertial>
    </link>
</robot>
